2023-02-12 17:22:36,820 INFO    StreamThr :5608 [internal.py:wandb_internal():87] W&B internal server running at pid: 5608, started at: 2023-02-12 17:22:36.820695
2023-02-12 17:22:36,828 DEBUG   HandlerThread:5608 [handler.py:handle_request():144] handle_request: status
2023-02-12 17:22:36,860 INFO    WriterThread:5608 [datastore.py:open_for_write():85] open: C:\Users\simplon\Desktop\Notebooks\Dossier_App_Fil_Rouge\notebook\wandb\run-20230212_172236-ciilw9js\run-ciilw9js.wandb
2023-02-12 17:22:36,860 DEBUG   SenderThread:5608 [sender.py:send():334] send: header
2023-02-12 17:22:36,950 DEBUG   SenderThread:5608 [sender.py:send():334] send: run
2023-02-12 17:22:40,524 INFO    SenderThread:5608 [retry.py:__call__():169] Retry attempt failed:
Traceback (most recent call last):
  File "C:\Users\simplon\anaconda3\lib\site-packages\urllib3\connection.py", line 174, in _new_conn
    conn = connection.create_connection(
  File "C:\Users\simplon\anaconda3\lib\site-packages\urllib3\util\connection.py", line 72, in create_connection
    for res in socket.getaddrinfo(host, port, family, socket.SOCK_STREAM):
  File "C:\Users\simplon\anaconda3\lib\socket.py", line 918, in getaddrinfo
    for res in _socket.getaddrinfo(host, port, family, type, proto, flags):
socket.gaierror: [Errno 11001] getaddrinfo failed

During handling of the above exception, another exception occurred:

Traceback (most recent call last):
  File "C:\Users\simplon\anaconda3\lib\site-packages\urllib3\connectionpool.py", line 703, in urlopen
    httplib_response = self._make_request(
  File "C:\Users\simplon\anaconda3\lib\site-packages\urllib3\connectionpool.py", line 386, in _make_request
    self._validate_conn(conn)
  File "C:\Users\simplon\anaconda3\lib\site-packages\urllib3\connectionpool.py", line 1042, in _validate_conn
    conn.connect()
  File "C:\Users\simplon\anaconda3\lib\site-packages\urllib3\connection.py", line 358, in connect
    self.sock = conn = self._new_conn()
  File "C:\Users\simplon\anaconda3\lib\site-packages\urllib3\connection.py", line 186, in _new_conn
    raise NewConnectionError(
urllib3.exceptions.NewConnectionError: <urllib3.connection.HTTPSConnection object at 0x000001D433CE4D30>: Failed to establish a new connection: [Errno 11001] getaddrinfo failed

During handling of the above exception, another exception occurred:

Traceback (most recent call last):
  File "C:\Users\simplon\anaconda3\lib\site-packages\requests\adapters.py", line 489, in send
    resp = conn.urlopen(
  File "C:\Users\simplon\anaconda3\lib\site-packages\urllib3\connectionpool.py", line 787, in urlopen
    retries = retries.increment(
  File "C:\Users\simplon\anaconda3\lib\site-packages\urllib3\util\retry.py", line 592, in increment
    raise MaxRetryError(_pool, url, error or ResponseError(cause))
urllib3.exceptions.MaxRetryError: HTTPSConnectionPool(host='api.wandb.ai', port=443): Max retries exceeded with url: /graphql (Caused by NewConnectionError('<urllib3.connection.HTTPSConnection object at 0x000001D433CE4D30>: Failed to establish a new connection: [Errno 11001] getaddrinfo failed'))

During handling of the above exception, another exception occurred:

Traceback (most recent call last):
  File "C:\Users\simplon\anaconda3\lib\site-packages\wandb\sdk\lib\retry.py", line 128, in __call__
    result = self._call_fn(*args, **kwargs)
  File "C:\Users\simplon\anaconda3\lib\site-packages\wandb\sdk\internal\internal_api.py", line 241, in execute
    return self.client.execute(*args, **kwargs)  # type: ignore
  File "C:\Users\simplon\anaconda3\lib\site-packages\wandb\vendor\gql-0.2.0\wandb_gql\client.py", line 52, in execute
    result = self._get_result(document, *args, **kwargs)
  File "C:\Users\simplon\anaconda3\lib\site-packages\wandb\vendor\gql-0.2.0\wandb_gql\client.py", line 60, in _get_result
    return self.transport.execute(document, *args, **kwargs)
  File "C:\Users\simplon\anaconda3\lib\site-packages\wandb\vendor\gql-0.2.0\wandb_gql\transport\requests.py", line 38, in execute
    request = requests.post(self.url, **post_args)
  File "C:\Users\simplon\anaconda3\lib\site-packages\requests\api.py", line 115, in post
    return request("post", url, data=data, json=json, **kwargs)
  File "C:\Users\simplon\anaconda3\lib\site-packages\requests\api.py", line 59, in request
    return session.request(method=method, url=url, **kwargs)
  File "C:\Users\simplon\anaconda3\lib\site-packages\requests\sessions.py", line 587, in request
    resp = self.send(prep, **send_kwargs)
  File "C:\Users\simplon\anaconda3\lib\site-packages\requests\sessions.py", line 701, in send
    r = adapter.send(request, **kwargs)
  File "C:\Users\simplon\anaconda3\lib\site-packages\requests\adapters.py", line 565, in send
    raise ConnectionError(e, request=request)
requests.exceptions.ConnectionError: HTTPSConnectionPool(host='api.wandb.ai', port=443): Max retries exceeded with url: /graphql (Caused by NewConnectionError('<urllib3.connection.HTTPSConnection object at 0x000001D433CE4D30>: Failed to establish a new connection: [Errno 11001] getaddrinfo failed'))
2023-02-12 17:22:42,001 DEBUG   HandlerThread:5608 [handler.py:handle_request():144] handle_request: keepalive
2023-02-12 17:22:47,054 DEBUG   HandlerThread:5608 [handler.py:handle_request():144] handle_request: keepalive
2023-02-12 17:22:52,101 DEBUG   HandlerThread:5608 [handler.py:handle_request():144] handle_request: keepalive
2023-02-12 17:22:57,124 DEBUG   HandlerThread:5608 [handler.py:handle_request():144] handle_request: keepalive
2023-02-12 17:23:02,147 DEBUG   HandlerThread:5608 [handler.py:handle_request():144] handle_request: keepalive
2023-02-12 17:23:07,179 DEBUG   HandlerThread:5608 [handler.py:handle_request():144] handle_request: keepalive
2023-02-12 17:23:12,210 DEBUG   HandlerThread:5608 [handler.py:handle_request():144] handle_request: keepalive
2023-02-12 17:23:17,256 DEBUG   HandlerThread:5608 [handler.py:handle_request():144] handle_request: keepalive
2023-02-12 17:23:22,287 DEBUG   HandlerThread:5608 [handler.py:handle_request():144] handle_request: keepalive
2023-02-12 17:23:27,326 DEBUG   HandlerThread:5608 [handler.py:handle_request():144] handle_request: keepalive
2023-02-12 17:23:32,379 DEBUG   HandlerThread:5608 [handler.py:handle_request():144] handle_request: keepalive
2023-02-12 17:23:37,393 DEBUG   HandlerThread:5608 [handler.py:handle_request():144] handle_request: cancel
2023-02-12 17:23:37,393 DEBUG   SenderThread:5608 [sender.py:send():343] Record cancelled: run
2023-02-12 17:23:37,393 DEBUG   HandlerThread:5608 [handler.py:handle_request():144] handle_request: cancel
2023-02-12 17:23:37,393 DEBUG   HandlerThread:5608 [handler.py:handle_request():144] handle_request: status_report
2023-02-12 17:23:41,279 INFO    MainThread:5608 [internal.py:handle_exit():77] Internal process exited
